<?xml version="1.0"?>
<!-- This URDF was automatically created by SolidWorks to URDF Exporter! Originally created by Stephen Brawner (brawner@gmail.com) 
     Commit Version: 1.6.0-1-g15f4949  Build Version: 1.6.7594.29634
     For more information, please see http://wiki.ros.org/sw_urdf_exporter -->
<!--created by your dad ,holmes-->
<robot xmlns:xacro="http://www.ros.org/wiki/xacro" name="dog_v4">
  
  <link name="world"/>

  <joint name="fixed" type="fixed">
    <parent link="world"/>
    <child link="body_link"/>
    <origin
      xyz="0 0 1"
      rpy="0 0 0" />
  </joint>

  <link name="body_link">/
    <inertial>
      <origin
        xyz="3.59365399029842E-08 2.29125606890368E-07 0.0454498530336411"
        rpy="0 0 0" />
      <mass
        value="25.0794314099621" />
      <inertia
        ixx="0.0822942642469674"
        ixy="-1.78120229421848E-08"
        ixz="8.54734089425751E-08"
        iyy="0.105805896621498"
        iyz="2.84371497321219E-07"
        izz="0.156039805240398" />
    </inertial>
    <visual>
      <origin
        xyz="0 0 0.025"
        rpy="0 0 0" />
      <geometry>
        <box size="0.28 0.1 0.05"/>
      </geometry>
      <material
        name="">
        <color
          rgba="0.6 0.6 0.6 1" />
      </material>
    </visual>
    <collision>
      <origin
        xyz="0 0 0.025"
        rpy="0 0 0" />
      <geometry>
        <box size="0.28 0.1 0.05"/>
      </geometry>
    </collision>
  </link>
  <link name="LF_top_link">
    <inertial>
      <origin
        xyz="0.02639 0.00062285 1.3269E-05"
        rpy="0 0 0" />
      <mass
        value="0.1574" />
      <inertia
        ixx="9.4106E-05"
        ixy="-9.8768E-07"
        ixz="-1.1286E-07"
        iyy="0.00012496"
        iyz="-9.7383E-09"
        izz="5.9686E-05" />
    </inertial>
    <visual>
      <origin
        xyz="0.0263235 0.010625 0"
        rpy="0 0 0" />
      <geometry>
        <box size="0.01 0.04 0.01"/>
      </geometry>
      <material
        name="">
        <color
          rgba="0.77647 0.75686 0.73725 1" />
      </material>
    </visual>
    <collision>
      <origin
        xyz="0.0263235 0.010625 0"
        rpy="0 0 0" />
      <geometry>
          <box size="0.01 0.04 0.01"/>
      </geometry>
    </collision>
  </link>
  <joint name="LF_top_joint" type="continuous">
    <origin
      xyz="0.141 0.05 0.04545"
      rpy="0 0 0" />
    <parent
      link="body_link" />
    <child
      link="LF_top_link" />
    <axis
      xyz="1 0 0" />
  </joint>
  <link name="LF_mid_link">
    <inertial>
      <origin
        xyz="-1.22483682477581E-05 0.0487648912011176 -0.0633406233333356"
        rpy="0 0 0" />
      <mass
        value="0.738937110035494" />
      <inertia
        ixx="0.00103721052037978"
        ixy="-2.04200549677798E-08"
        ixz="-4.21702731113156E-08"
        iyy="0.00123011741777564"
        iyz="1.52024995628507E-05"
        izz="0.000267793821007483" />
    </inertial>
    <visual>
      <origin
        xyz=' 0.000 0.02675 -0.10569 '
        rpy="0 0 0" />
      <geometry>
        <box size="0.01 0.01 -0.21138"/>
      </geometry>
      <material
        name="">
        <color
          rgba="0.776470588235294 0.756862745098039 0.737254901960784 1" />
      </material>
    </visual>
    <collision>
      <origin
        xyz=' 0.000 0.02675 -0.10569 '
        rpy="0 0 0" />
      <geometry>
          <box size="0.01 0.01 -0.21138"/>
      </geometry>
    </collision>
  </link>
  <joint name="LF_mid_joint" type="continuous">
    <origin
      xyz="0.052647 0.02125 9.2724E-05"
      rpy="0 0 0" />
    <parent
      link="LF_top_link" />
    <child
      link="LF_mid_link" />
    <axis
      xyz="0 -1 0" />
  </joint>
  <link name="LF_down_link">
    <inertial>
      <origin
        xyz="-5.2121634081137E-05 0.00100252547655214 -0.0734382702906037"
        rpy="0 0 0" />
      <mass
        value="0.300551677258286" />
      <inertia
        ixx="0.000336998224662871"
        ixy="5.09859916248364E-11"
        ixz="1.16147313952368E-10"
        iyy="0.000352769216727733"
        iyz="-1.47711505397845E-11"
        izz="2.93076635016167E-05" />
    </inertial>
    <visual>
      <origin
        xyz="0 0.0 -0.1"
        rpy="0 0 0" />
      <geometry>
        <box size="0.01 0.01 0.2"/>
      </geometry>
      <material
        name="">
        <color
          rgba="0.776470588235294 0.756862745098039 0.737254901960784 1" />
      </material>
    </visual>
    <collision>
      <origin
        xyz="0 0 -0.1"
        rpy="0 0 0" />
      <geometry>
        <box size="0.01 0.01 0.2"/>
      </geometry>
    </collision>
  </link>
  <joint name="LF_down_joint" type="continuous">
    <origin
      xyz="0 0.0535 -0.21138"
      rpy="0 0 0" />
    <parent
      link="LF_mid_link" />
    <child
      link="LF_down_link" />
    <axis
      xyz="0 -1 0" />
  </joint>
  <link
    name="RF_top_link">
    <inertial>
      <origin
        xyz="0.0263901999841434 -0.000622848908864299 -1.32687268125098E-05"
        rpy="0 0 0" />
      <mass
        value="0.15740044195971" />
      <inertia
        ixx="9.41058670909895E-05"
        ixy="9.87683421374913E-07"
        ixz="1.1285668464894E-07"
        iyy="0.00012495859879355"
        iyz="-9.73826160045511E-09"
        izz="5.96858784543533E-05" />
    </inertial>
    <visual>
      <origin
        xyz=" 0.0263235 -0.010625 4.6362e-05 "
        rpy="0 0 0" />
      <geometry>
          <box size="0.01 0.04 0.01"/>
      </geometry>
      <material
        name="">
        <color
          rgba="0.776470588235294 0.756862745098039 0.737254901960784 1" />
      </material>
    </visual>
    <collision>
      <origin
        xyz=" 0.0263235 -0.010625 4.6362e-05 "
        rpy="0 0 0" />
      <geometry>
        <box size="0.01 0.04 0.01"/>
      </geometry>
    </collision>
  </link>
  <joint
    name="RF_top_joint"
    type="continuous">
    <origin
      xyz="0.141 -0.05 0.04545"
      rpy="0 0 0" />
    <parent
      link="body_link" />
    <child
      link="RF_top_link" />
    <axis
      xyz="1 0 0" />
  </joint>
  <link
    name="RF_mid_link">
    <inertial>
      <origin
        xyz="7.52172599330359E-05 -0.0487649107544759 -0.063515028561511"
        rpy="0 0 0" />
      <mass
        value="0.738937036461301" />
      <inertia
        ixx="0.0010372109312777"
        ixy="-2.04489930527831E-08"
        ixz="3.64841294031766E-08"
        iyy="0.0012301178223017"
        iyz="-1.52021638758677E-05"
        izz="0.000267793766462554" />
    </inertial>
    <visual>
      <origin
        xyz=" 0 -0.02675 -0.10578 "
        rpy="0 0 0" />
      <geometry>
          <box size="0.01 -0.01 -0.21156"/>
      </geometry>
      <material
        name="">
        <color
          rgba="0.6 0.6 0.6 1" />
      </material>
    </visual>
    <collision>
      <origin
        xyz=" 0 -0.02675 -0.10578 "
        rpy="0 0 0" />
      <geometry>
          <box size="0.01 -0.01 -0.21156"/>
      </geometry>
    </collision>
  </link>
  <joint
    name="RF_mid_joint"
    type="continuous">
    <origin
      xyz="0.052647 -0.02125 9.2724E-05"
      rpy="0 0 0" />
    <parent
      link="RF_top_link" />
    <child
      link="RF_mid_link" />
    <axis
      xyz="0 -1 0" />
  </joint>
  <link
    name="RF_down_link">
    <inertial>
      <origin
        xyz="5.21297187678349E-05 -0.00100252409918886 -0.0734382823671863"
        rpy="0 0 0" />
      <mass
        value="0.300551781300463" />
      <inertia
        ixx="0.000336998255214494"
        ixy="4.78659762699933E-11"
        ixz="1.16223885811268E-10"
        iyy="0.000352769237624744"
        iyz="1.32635609364215E-11"
        izz="2.93076599310258E-05" />
    </inertial>
    <visual>
      <origin
        xyz="0 0 -0.1"
        rpy="0 0 0" />
      <geometry>
        <box size="0.01 0.01 0.2"/>
      </geometry>
      <material
        name="">
        <color
          rgba="0.776470588235294 0.756862745098039 0.737254901960784 1" />
      </material>
    </visual>
    <collision>
      <origin
        xyz="0 0 -0.1"
        rpy="0 0 0" />
      <geometry>
        <box size="0.01 0.01 0.2"/>
      </geometry>
    </collision>
  </link>
  <joint
    name="RF_down_joint"
    type="continuous">
    <origin
      xyz="6.3049E-05 -0.0535 -0.21156"
      rpy="0 0 0" />
    <parent
      link="RF_mid_link" />
    <child
      link="RF_down_link" />
    <axis
      xyz="0 -1 0" />
  </joint>
  <link
    name="LB_top_link">
    <inertial>
      <origin
        xyz="-0.0263901989657993 0.000622847753819405 -1.32687274303489E-05"
        rpy="0 0 0" />
      <mass
        value="0.157400449286954" />
      <inertia
        ixx="9.41058660743391E-05"
        ixy="9.87684273498811E-07"
        ixz="-1.12856623194467E-07"
        iyy="0.000124958594900212"
        iyz="9.73826057587375E-09"
        izz="5.96858816789111E-05" />
    </inertial>
    <visual>
      <origin
        xyz=" -0.0263235 0.010625 4.6362e-05 "
        rpy="0 0 0" />
      <geometry>
        <box size="0.01 0.04 0.01"/>
      </geometry>
      <material
        name="">
        <color
          rgba="0.776470588235294 0.756862745098039 0.737254901960784 1" />
      </material>
    </visual>
    <collision>
      <origin
        xyz=" -0.0263235 0.010625 4.6362e-05 "
        rpy="0 0 0" />
      <geometry>
        <box size="0.01 0.04 0.01"/>
      </geometry>
    </collision>
  </link>
  <joint
    name="LB_top_joint"
    type="continuous">
    <origin
      xyz="-0.141 0.05 0.04545"
      rpy="0 0 0" />
    <parent
      link="body_link" />
    <child
      link="LB_top_link" />
    <axis
      xyz="1 0 0" />
  </joint>
  <link
    name="LB_mid_link">
    <inertial>
      <origin
        xyz="0.00010365 0.048765 -0.063485"
        rpy="0 0 0" />
      <mass
        value="0.73894" />
      <inertia
        ixx="0.0010372"
        ixy="-2.0457E-08"
        ixz="-3.9998E-08"
        iyy="0.0012301"
        iyz="1.5202E-05"
        izz="0.00026779" />
    </inertial>
    <visual>
      <origin
        xyz=" 0 0.02675 -0.105765 "
        rpy="0 0 0" />
      <geometry>
        <box size="0.01 0.01 -0.21153"/>
      </geometry>
      <material
        name="">
        <color
          rgba="0.6 0.6 0.6 1" />
      </material>
    </visual>
    <collision>
      <origin
        xyz="0 0.02675 -0.105765 "
        rpy="0 0 0" />
      <geometry>
        <box size="0.01 0.01 -0.21153"/>
      </geometry>
    </collision>
  </link>
  <joint
    name="LB_mid_joint"
    type="continuous">
    <origin
      xyz="-0.052647 0.02125 9.2724E-05"
      rpy="0 0 0" />
    <parent
      link="LB_top_link" />
    <child
      link="LB_mid_link" />
    <axis
      xyz="0 -1 0" />
  </joint>
  <link
    name="LB_down_link">
    <inertial>
      <origin
        xyz="-5.21254997021825E-05 0.00100252557683615 -0.073438254514421"
        rpy="0 0 0" />
      <mass
        value="0.300551676792456" />
      <inertia
        ixx="0.000336998282459304"
        ixy="4.86629441623418E-11"
        ixz="-3.49945646767292E-11"
        iyy="0.000352769263569714"
        iyz="-1.77505288707495E-11"
        izz="2.93076582702725E-05" />
    </inertial>
    <visual>
      <origin
        xyz="0 0 -0.1"
        rpy="0 0 0" />
      <geometry>
        <box size="0.01 0.01 0.2"/>
      </geometry>
      <material
        name="">
        <color
          rgba="0.776470588235294 0.756862745098039 0.737254901960784 1" />
      </material>
    </visual>
    <collision>
      <origin
        xyz="0 0 -0.1"
        rpy="0 0 0" />
      <geometry>
        <box size="0.01 0.01 0.2"/>
      </geometry>
    </collision>
  </link>
  <joint
    name="LB_down_joint"
    type="continuous">
    <origin
      xyz="0.00011587 0.0535 -0.21153"
      rpy="0 0 0" />
    <parent
      link="LB_mid_link" />
    <child
      link="LB_down_link" />
    <axis
      xyz="0 -1 0" />
  </joint>

  <link name="RB_top_link">
    <inertial>
      <origin
        xyz="-0.0263901989657993 -0.000622847753819405 1.32687274303489E-05"
        rpy="0 0 0" />
      <mass
        value="0.15740044195971" />
      <inertia
        ixx="9.41058660743391E-05"
        ixy="-9.87684273498811E-07"
        ixz="1.12856623194467E-07"
        iyy="0.000124958594900212"
        iyz="9.73826057587375E-09"
        izz="5.96858816789111E-05" />
    </inertial>

    <visual>
      <origin
        xyz=" -0.0263235 -0.010625 4.6362e-05 "
        rpy="0 0 0" />
      <geometry>
        <box size="0.01 0.04 0.01"/>
      </geometry>
      <material
        name="">
        <color
          rgba="1 1 1 1" />
      </material>
    </visual>
    <collision>
      <origin
        xyz=" -0.0263235 -0.010625 4.6362e-05 "
        rpy="0 0 0" />
      <geometry>
        <box size="0.01 0.04 0.01"/>
      </geometry>
    </collision>
  </link>
  <joint
    name="RB_top_joint"
    type="continuous">
    <origin
      xyz="-0.141 -0.05 0.04545"
      rpy="0 0 0" />
    <parent
      link="body_link" />
    <child
      link="RB_top_link" />
    <axis
      xyz="1 0 0" />
  </joint>
  <link
    name="RB_mid_link">
    <inertial>
      <origin
        xyz="1.221E-05 -0.048765 -0.063341"
        rpy="0 0 0" />
      <mass
        value="0.73894" />
      <inertia
        ixx="0.0010372"
        ixy="-2.0454E-08"
        ixz="3.9548E-08"
        iyy="0.0012301"
        iyz="-1.5202E-05"
        izz="0.00026779" />
    </inertial>
    <visual>
      <origin
        xyz=" 0.0 -0.02675 -0.10569 "
        rpy="0 0 0" />
      <geometry>
          <box size="0.01 0.01 -0.21138"/>
      </geometry>
      <material
        name="">
        <color
          rgba="0.6 0.6 0.6 1" />
      </material>
    </visual>
    <collision>
      <origin
        xyz=" 0.0 -0.02675 -0.10569 "
        rpy="0 0 0" />
      <geometry>
        <box size="0.01 0.01 -0.21138"/>
      </geometry>
    </collision>
  </link>
  <joint
    name="RB_mid_joint"
    type="continuous">
    <origin
      xyz="-0.052647 -0.02125 9.2724E-05"
      rpy="0 0 0" />
    <parent
      link="RB_top_link" />
    <child
      link="RB_mid_link" />
    <axis
      xyz="0 -1 0" />
  </joint>
  <link
    name="RB_down_link">
    <inertial>
      <origin
        xyz="5.2122E-05 -0.0010025 -0.073438"
        rpy="0 0 0" />
      <mass
        value="0.30055" />
      <inertia
        ixx="0.000337"
        ixy="5.026E-11"
        ixz="-1.1469E-10"
        iyy="0.00035277"
        iyz="1.4367E-11"
        izz="2.9308E-05" />
    </inertial>
    <visual>
      <origin
        xyz="0 0 -0.1"
        rpy="0 0 0" />
      <geometry>
        <box size="0.01 0.01 0.2"/>
      </geometry>
      <material
        name="">
        <color
          rgba="0.77647 0.75686 0.73725 1" />
      </material>
    </visual>
    <collision>
      <origin
        xyz="0 0 -0.1"
        rpy="0 0 0" />
      <geometry>
        <box size="0.01 0.01 0.2"/>
      </geometry>
    </collision>
  </link>
  <joint
    name="RB_down_joint"
    type="continuous">
    <origin
      xyz="0 -0.0535 -0.21138"
      rpy="0 0 0" />
    <parent
      link="RB_mid_link" />
    <child
      link="RB_down_link" />
    <axis
      xyz="0 -1 0" />
  </joint>

  <xacro:include filename="$(find dog_v4)/urdf/dog_v4_gazebo.xacro"/>
  
  <xacro:include filename="$(find dog_v4)/urdf/dog_v4_trans.xacro"/>
</robot>
