<?xml version="1.0" encoding="utf-8"?>
<!-- =================================================================================== -->
<!-- |    This document was autogenerated by xacro from dog_v4.xacro                   | -->
<!-- |    EDITING THIS FILE BY HAND IS NOT RECOMMENDED                                 | -->
<!-- =================================================================================== -->
<!-- This URDF was automatically created by SolidWorks to URDF Exporter! Originally created by Stephen Brawner (brawner@gmail.com) 
     Commit Version: 1.6.0-1-g15f4949  Build Version: 1.6.7594.29634
     For more information, please see http://wiki.ros.org/sw_urdf_exporter -->
<!--created by your dad ,holmes-->
<robot name="dog_v4">

  <link name="body_link">
    <inertial>
      <origin rpy="0 0 0" xyz="3.59365399029842E-08 2.29125606890368E-07 0.0454498530336411"/>
      <mass value="25.0794314099621"/>
      <inertia ixx="0.0822942642469674" ixy="-1.78120229421848E-08" ixz="8.54734089425751E-08" iyy="0.105805896621498" iyz="2.84371497321219E-07" izz="0.156039805240398"/>
    </inertial>
    <visual>
      <origin rpy="0 0 0" xyz="0 0 0"/>
      <geometry>
        <mesh filename="package://dog_v4/meshes/body_link.STL"/>
      </geometry>
      <material name="">
        <color rgba="0.6 0.6 0.6 1"/>
      </material>
    </visual>
    <collision>
      <origin rpy="0 0 0" xyz="0 0 0"/>
      <geometry>
        <mesh filename="package://dog_v4/meshes/body_link.STL"/>
      </geometry>
    </collision>
  </link>
  <link name="LF_top_link">
    <inertial>
      <origin rpy="0 0 0" xyz="0.02639 0.00062285 1.3269E-05"/>
      <mass value="0.1574"/>
      <inertia ixx="9.4106E-05" ixy="-9.8768E-07" ixz="-1.1286E-07" iyy="0.00012496" iyz="-9.7383E-09" izz="5.9686E-05"/>
    </inertial>
    <visual>
      <origin rpy="0 0 0" xyz="0 0 0"/>
      <geometry>
        <mesh filename="package://dog_v4/meshes/LF_top_link.STL"/>
      </geometry>
      <material name="">
        <color rgba="0.77647 0.75686 0.73725 1"/>
      </material>
    </visual>
    <collision>
      <origin rpy="0 0 0" xyz="0 0 0"/>
      <geometry>
        <mesh filename="package://dog_v4/meshes/LF_top_link.STL"/>
      </geometry>
    </collision>
  </link>
  <joint name="LF_top_joint" type="revolute">
    <origin rpy="0 0 0" xyz="0.141 0.05 0.04545"/>
    <parent link="body_link"/>
    <child link="LF_top_link"/>
    <axis xyz="1 0 0"/>
    <limit lower="-1.57" upper="1.57" effort="100.0" velocity="5.0"/>
    <dynamics damping="0.0" friction="0.0"/>
  </joint>
  <link name="LF_mid_link">
    <inertial>
      <origin rpy="0 0 0" xyz="-1.22483682477581E-05 0.0487648912011176 -0.0633406233333356"/>
      <mass value="0.738937110035494"/>
      <inertia ixx="0.00103721052037978" ixy="-2.04200549677798E-08" ixz="-4.21702731113156E-08" iyy="0.00123011741777564" iyz="1.52024995628507E-05" izz="0.000267793821007483"/>
    </inertial>
    <visual>
      <origin rpy="0 0 0" xyz="0 0 0"/>
      <geometry>
        <mesh filename="package://dog_v4/meshes/LF_mid_link.STL"/>
      </geometry>
      <material name="">
        <color rgba="0.776470588235294 0.756862745098039 0.737254901960784 1"/>
      </material>
    </visual>
    <collision>
      <origin rpy="0 0 0" xyz="0 0 0"/>
      <geometry>
        <mesh filename="package://dog_v4/meshes/LF_mid_link.STL"/>
      </geometry>
    </collision>
  </link>
  <joint name="LF_mid_joint" type="revolute">
    <origin rpy="0 0 0" xyz="0.052647 0.02125 9.2724E-05"/>
    <parent link="LF_top_link"/>
    <child link="LF_mid_link"/>
    <axis xyz="0 1 0"/>
    <limit lower="-1.57" upper="1.57" effort="100.0" velocity="5.0"/>
    <dynamics damping="0.0" friction="0.0"/>
  </joint>
  <link name="LF_down_link">
    <inertial>
      <origin rpy="0 0 0" xyz="-5.2121634081137E-05 0.00100252547655214 -0.0734382702906037"/>
      <mass value="0.300551677258286"/>
      <inertia ixx="0.000336998224662871" ixy="5.09859916248364E-11" ixz="1.16147313952368E-10" iyy="0.000352769216727733" iyz="-1.47711505397845E-11" izz="2.93076635016167E-05"/>
    </inertial>
    <visual>
      <origin rpy="0 0 0" xyz="0 0 0"/>
      <geometry>
        <mesh filename="package://dog_v4/meshes/LF_down_link.STL"/>
      </geometry>
      <material name="">
        <color rgba="0.776470588235294 0.756862745098039 0.737254901960784 1"/>
      </material>
    </visual>
    <collision>
      <origin rpy="0 0 0" xyz="0 0 0"/>
      <geometry>
        <mesh filename="package://dog_v4/meshes/LF_down_link.STL"/>
      </geometry>
    </collision>
  </link>
  <joint name="LF_down_joint" type="revolute">
    <origin rpy="0 0 0" xyz="0 0.0535 -0.21138"/>
    <parent link="LF_mid_link"/>
    <child link="LF_down_link"/>
    <axis xyz="0 1 0"/>
    <limit lower="-1.57" upper="1.57" effort="100.0" velocity="5.0"/>
    <dynamics damping="0.0" friction="0.0"/>
  </joint>
  <link name="RF_top_link">
    <inertial>
      <origin rpy="0 0 0" xyz="0.0263901999841434 -0.000622848908864299 -1.32687268125098E-05"/>
      <mass value="0.15740044195971"/>
      <inertia ixx="9.41058670909895E-05" ixy="9.87683421374913E-07" ixz="1.1285668464894E-07" iyy="0.00012495859879355" iyz="-9.73826160045511E-09" izz="5.96858784543533E-05"/>
    </inertial>
    <visual>
      <origin rpy="0 0 0" xyz="0 0 0"/>
      <geometry>
        <mesh filename="package://dog_v4/meshes/RF_top_link.STL"/>
      </geometry>
      <material name="">
        <color rgba="0.776470588235294 0.756862745098039 0.737254901960784 1"/>
      </material>
    </visual>
    <collision>
      <origin rpy="0 0 0" xyz="0 0 0"/>
      <geometry>
        <mesh filename="package://dog_v4/meshes/RF_top_link.STL"/>
      </geometry>
    </collision>
  </link>
  <joint name="RF_top_joint" type="revolute">
    <origin rpy="0 0 0" xyz="0.141 -0.05 0.04545"/>
    <parent link="body_link"/>
    <child link="RF_top_link"/>
    <axis xyz="1 0 0"/>
    <limit lower="-1.57" upper="1.57" effort="100.0" velocity="5.0"/>
    <dynamics damping="0.0" friction="0.0"/>
  </joint>
  <link name="RF_mid_link">
    <inertial>
      <origin rpy="0 0 0" xyz="7.52172599330359E-05 -0.0487649107544759 -0.063515028561511"/>
      <mass value="0.738937036461301"/>
      <inertia ixx="0.0010372109312777" ixy="-2.04489930527831E-08" ixz="3.64841294031766E-08" iyy="0.0012301178223017" iyz="-1.52021638758677E-05" izz="0.000267793766462554"/>
    </inertial>
    <visual>
      <origin rpy="0 0 0" xyz="0 0 0"/>
      <geometry>
        <mesh filename="package://dog_v4/meshes/RF_mid_link.STL"/>
      </geometry>
      <material name="">
        <color rgba="0.6 0.6 0.6 1"/>
      </material>
    </visual>
    <collision>
      <origin rpy="0 0 0" xyz="0 0 0"/>
      <geometry>
        <mesh filename="package://dog_v4/meshes/RF_mid_link.STL"/>
      </geometry>
    </collision>
  </link>
  <joint name="RF_mid_joint" type="revolute">
    <origin rpy="0 0 0" xyz="0.052647 -0.02125 9.2724E-05"/>
    <parent link="RF_top_link"/>
    <child link="RF_mid_link"/>
    <axis xyz="0 1 0"/>
    <limit lower="-1.57" upper="1.57" effort="100.0" velocity="5.0"/>
    <dynamics damping="0.0" friction="0.0"/>
  </joint>
  <link name="RF_down_link">
    <inertial>
      <origin rpy="0 0 0" xyz="5.21297187678349E-05 -0.00100252409918886 -0.0734382823671863"/>
      <mass value="0.300551781300463"/>
      <inertia ixx="0.000336998255214494" ixy="4.78659762699933E-11" ixz="1.16223885811268E-10" iyy="0.000352769237624744" iyz="1.32635609364215E-11" izz="2.93076599310258E-05"/>
    </inertial>
    <visual>
      <origin rpy="0 0 0" xyz="0 0 0"/>
      <geometry>
        <mesh filename="package://dog_v4/meshes/RF_down_link.STL"/>
      </geometry>
      <material name="">
        <color rgba="0.776470588235294 0.756862745098039 0.737254901960784 1"/>
      </material>
    </visual>
    <collision>
      <origin rpy="0 0 0" xyz="0 0 0"/>
      <geometry>
        <mesh filename="package://dog_v4/meshes/RF_down_link.STL"/>
      </geometry>
    </collision>
  </link>
  <joint name="RF_down_joint" type="revolute">
    <origin rpy="0 0 0" xyz="6.3049E-05 -0.0535 -0.21156"/>
    <parent link="RF_mid_link"/>
    <child link="RF_down_link"/>
    <axis xyz="0 1 0"/>
    <limit lower="-1.57" upper="1.57" effort="100.0" velocity="5.0"/>
    <dynamics damping="0.0" friction="0.0"/>
  </joint>
  <link name="LB_top_link">
    <inertial>
      <origin rpy="0 0 0" xyz="-0.0263901989657993 0.000622847753819405 -1.32687274303489E-05"/>
      <mass value="0.157400449286954"/>
      <inertia ixx="9.41058660743391E-05" ixy="9.87684273498811E-07" ixz="-1.12856623194467E-07" iyy="0.000124958594900212" iyz="9.73826057587375E-09" izz="5.96858816789111E-05"/>
    </inertial>
    <visual>
      <origin rpy="0 0 0" xyz="0 0 0"/>
      <geometry>
        <mesh filename="package://dog_v4/meshes/LB_top_link.STL"/>
      </geometry>
      <material name="">
        <color rgba="0.776470588235294 0.756862745098039 0.737254901960784 1"/>
      </material>
    </visual>
    <collision>
      <origin rpy="0 0 0" xyz="0 0 0"/>
      <geometry>
        <mesh filename="package://dog_v4/meshes/LB_top_link.STL"/>
      </geometry>
    </collision>
  </link>
  <joint name="LB_top_joint" type="revolute">
    <origin rpy="0 0 0" xyz="-0.141 0.05 0.04545"/>
    <parent link="body_link"/>
    <child link="LB_top_link"/>
    <axis xyz="1 0 0"/>
    <limit lower="-1.57" upper="1.57" effort="100.0" velocity="5.0"/>
    <dynamics damping="0.0" friction="0.0"/>
  </joint>
  <link name="LB_mid_link">
    <inertial>
      <origin rpy="0 0 0" xyz="0.00010365 0.048765 -0.063485"/>
      <mass value="0.73894"/>
      <inertia ixx="0.0010372" ixy="-2.0457E-08" ixz="-3.9998E-08" iyy="0.0012301" iyz="1.5202E-05" izz="0.00026779"/>
    </inertial>
    <visual>
      <origin rpy="0 0 0" xyz="0 0 0"/>
      <geometry>
        <mesh filename="package://dog_v4/meshes/LB_mid_link.STL"/>
      </geometry>
      <material name="">
        <color rgba="0.6 0.6 0.6 1"/>
      </material>
    </visual>
    <collision>
      <origin rpy="0 0 0" xyz="0 0 0"/>
      <geometry>
        <mesh filename="package://dog_v4/meshes/LB_mid_link.STL"/>
      </geometry>
    </collision>
  </link>
  <joint name="LB_mid_joint" type="revolute">
    <origin rpy="0 0 0" xyz="-0.052647 0.02125 9.2724E-05"/>
    <parent link="LB_top_link"/>
    <child link="LB_mid_link"/>
    <axis xyz="0 1 0"/>
    <limit lower="-1.57" upper="1.57" effort="100.0" velocity="5.0"/>
    <dynamics damping="0.0" friction="0.0"/>
  </joint>
  <link name="LB_down_link">
    <inertial>
      <origin rpy="0 0 0" xyz="-5.21254997021825E-05 0.00100252557683615 -0.073438254514421"/>
      <mass value="0.300551676792456"/>
      <inertia ixx="0.000336998282459304" ixy="4.86629441623418E-11" ixz="-3.49945646767292E-11" iyy="0.000352769263569714" iyz="-1.77505288707495E-11" izz="2.93076582702725E-05"/>
    </inertial>
    <visual>
      <origin rpy="0 0 0" xyz="0 0 0"/>
      <geometry>
        <mesh filename="package://dog_v4/meshes/LB_down_link.STL"/>
      </geometry>
      <material name="">
        <color rgba="0.776470588235294 0.756862745098039 0.737254901960784 1"/>
      </material>
    </visual>
    <collision>
      <origin rpy="0 0 0" xyz="0 0 0"/>
      <geometry>
        <mesh filename="package://dog_v4/meshes/LB_down_link.STL"/>
      </geometry>
    </collision>
  </link>
  <joint name="LB_down_joint" type="revolute">
    <origin rpy="0 0 0" xyz="0.00011587 0.0535 -0.21153"/>
    <parent link="LB_mid_link"/>
    <child link="LB_down_link"/>
    <axis xyz="0 1 0"/>
    <limit lower="-1.57" upper="1.57" effort="100.0" velocity="5.0"/>
    <dynamics damping="0.0" friction="0.0"/>
  </joint>
  <link name="RB_top_link">
    <inertial>
      <origin rpy="0 0 0" xyz="-0.0263901989657993 -0.000622847753819405 1.32687274303489E-05"/>
      <mass value="0.15740044195971"/>
      <inertia ixx="9.41058660743391E-05" ixy="-9.87684273498811E-07" ixz="1.12856623194467E-07" iyy="0.000124958594900212" iyz="9.73826057587375E-09" izz="5.96858816789111E-05"/>
    </inertial>
    <visual>
      <origin rpy="0 0 0" xyz="0 0 0"/>
      <geometry>
        <mesh filename="package://dog_v4/meshes/RB_top_link.STL"/>
      </geometry>
      <material name="">
        <color rgba="1 1 1 1"/>
      </material>
    </visual>
    <collision>
      <origin rpy="0 0 0" xyz="0 0 0"/>
      <geometry>
        <mesh filename="package://dog_v4/meshes/RB_top_link.STL"/>
      </geometry>
    </collision>
  </link>
  <joint name="RB_top_joint" type="revolute">
    <origin rpy="0 0 0" xyz="-0.141 -0.05 0.04545"/>
    <parent link="body_link"/>
    <child link="RB_top_link"/>
    <axis xyz="1 0 0"/>
    <limit lower="-1.57" upper="1.57" effort="100.0" velocity="5.0"/>
    <dynamics damping="0.0" friction="0.0"/>
  </joint>
  <link name="RB_mid_link">
    <inertial>
      <origin rpy="0 0 0" xyz="1.221E-05 -0.048765 -0.063341"/>
      <mass value="0.73894"/>
      <inertia ixx="0.0010372" ixy="-2.0454E-08" ixz="3.9548E-08" iyy="0.0012301" iyz="-1.5202E-05" izz="0.00026779"/>
    </inertial>
    <visual>
      <origin rpy="0 0 0" xyz="0 0 0"/>
      <geometry>
        <mesh filename="package://dog_v4/meshes/RB_mid_link.STL"/>
      </geometry>
      <material name="">
        <color rgba="0.6 0.6 0.6 1"/>
      </material>
    </visual>
    <collision>
      <origin rpy="0 0 0" xyz="0 0 0"/>
      <geometry>
        <mesh filename="package://dog_v4/meshes/RB_mid_link.STL"/>
      </geometry>
    </collision>
  </link>
  <joint name="RB_mid_joint" type="revolute">
    <origin rpy="0 0 0" xyz="-0.052647 -0.02125 9.2724E-05"/>
    <parent link="RB_top_link"/>
    <child link="RB_mid_link"/>
    <axis xyz="0 1 0"/>
    <limit lower="-1.57" upper="1.57" effort="100.0" velocity="5.0"/>
    <dynamics damping="0.0" friction="0.0"/>
  </joint>
  <link name="RB_down_link">
    <inertial>
      <origin rpy="0 0 0" xyz="5.2122E-05 -0.0010025 -0.073438"/>
      <mass value="0.30055"/>
      <inertia ixx="0.000337" ixy="5.026E-11" ixz="-1.1469E-10" iyy="0.00035277" iyz="1.4367E-11" izz="2.9308E-05"/>
    </inertial>
    <visual>
      <origin rpy="0 0 0" xyz="0 0 0"/>
      <geometry>
        <mesh filename="package://dog_v4/meshes/RB_down_link.STL"/>
      </geometry>
      <material name="">
        <color rgba="0.77647 0.75686 0.73725 1"/>
      </material>
    </visual>
    <collision>
      <origin rpy="0 0 0" xyz="0 0 0"/>
      <geometry>
        <mesh filename="package://dog_v4/meshes/RB_down_link.STL"/>
      </geometry>
    </collision>
  </link>
  <joint name="RB_down_joint" type="revolute">
    <origin rpy="0 0 0" xyz="0 -0.0535 -0.21138"/>
    <parent link="RB_mid_link"/>
    <child link="RB_down_link"/>
    <axis xyz="0 1 0"/>
    <limit lower="-1.57" upper="1.57" effort="100.0" velocity="5.0"/>
    <dynamics damping="0.0" friction="0.0"/>
  </joint>

  <transmission name="LF_top_trans">
    <type>transmission_interface/SimpleTransmission</type>
    <joint name="LF_top_joint">
      <hardwareInterface>hardware_interface/EffortJointInterface</hardwareInterface>
      <!--Note that the value of this tag should be EffortJointInterface when this transmission is loaded in Gazebo -->
    </joint>
    <actuator name="LF_top_motor">
      <!--An actuator the transmission is connected to. The actuator is specified by its name attribute, and the following sub-elements -->
      <mechanicalReduction>10</mechanicalReduction>
      <hardwareInterface>hardware_interface/EffortJointInterface</hardwareInterface>
    </actuator>
  </transmission>

  <transmission name="LF_mid_trans">
    <type>transmission_interface/SimpleTransmission</type>
    <joint name="LF_mid_joint">
      <hardwareInterface>hardware_interface/EffortJointInterface</hardwareInterface>
      <!--Note that the value of this tag should be EffortJointInterface when this transmission is loaded in Gazebo -->
    </joint>
    <actuator name="LF_mid_motor">
      <!--An actuator the transmission is connected to. The actuator is specified by its name attribute, and the following sub-elements -->
      <mechanicalReduction>10</mechanicalReduction>
      <hardwareInterface>hardware_interface/EffortJointInterface</hardwareInterface>
    </actuator>
  </transmission>

  <transmission name="LF_down_trans">
    <type>transmission_interface/SimpleTransmission</type>
    <joint name="LF_down_joint">
      <hardwareInterface>hardware_interface/EffortJointInterface</hardwareInterface>
      <!--Note that the value of this tag should be EffortJointInterface when this transmission is loaded in Gazebo -->
    </joint>
    <actuator name="LF_down_motor">
      <!--An actuator the transmission is connected to. The actuator is specified by its name attribute, and the following sub-elements -->
      <mechanicalReduction>10</mechanicalReduction>
      <hardwareInterface>hardware_interface/EffortJointInterface</hardwareInterface>
    </actuator>
  </transmission>

  <transmission name="RF_top_trans">
    <type>transmission_interface/SimpleTransmission</type>
    <joint name="RF_top_joint">
      <hardwareInterface>hardware_interface/EffortJointInterface</hardwareInterface>
      <!--Note that the value of this tag should be EffortJointInterface when this transmission is loaded in Gazebo -->
    </joint>
    <actuator name="RF_top_motor">
      <!--An actuator the transmission is connected to. The actuator is specified by its name attribute, and the following sub-elements -->
      <mechanicalReduction>10</mechanicalReduction>
      <hardwareInterface>hardware_interface/EffortJointInterface</hardwareInterface>
    </actuator>
  </transmission>

  <transmission name="RF_mid_trans">
    <type>transmission_interface/SimpleTransmission</type>
    <joint name="RF_mid_joint">
      <hardwareInterface>hardware_interface/EffortJointInterface</hardwareInterface>
      <!--Note that the value of this tag should be EffortJointInterface when this transmission is loaded in Gazebo -->
    </joint>
    <actuator name="RF_mid_motor">
      <!--An actuator the transmission is connected to. The actuator is specified by its name attribute, and the following sub-elements -->
      <mechanicalReduction>10</mechanicalReduction>
      <hardwareInterface>hardware_interface/EffortJointInterface</hardwareInterface>
    </actuator>
  </transmission>

  <transmission name="RF_down_trans">
    <type>transmission_interface/SimpleTransmission</type>
    <joint name="RF_down_joint">
      <hardwareInterface>hardware_interface/EffortJointInterface</hardwareInterface>
      <!--Note that the value of this tag should be EffortJointInterface when this transmission is loaded in Gazebo -->
    </joint>
    <actuator name="RF_down_motor">
      <!--An actuator the transmission is connected to. The actuator is specified by its name attribute, and the following sub-elements -->
      <mechanicalReduction>10</mechanicalReduction>
      <hardwareInterface>hardware_interface/EffortJointInterface</hardwareInterface>
    </actuator>
  </transmission>

  <transmission name="LB_top_trans">
    <type>transmission_interface/SimpleTransmission</type>
    <joint name="LB_top_joint">
      <hardwareInterface>hardware_interface/EffortJointInterface</hardwareInterface>
      <!--Note that the value of this tag should be EffortJointInterface when this transmission is loaded in Gazebo -->
    </joint>
    <actuator name="LB_top_motor">
      <!--An actuator the transmission is connected to. The actuator is specified by its name attribute, and the following sub-elements -->
      <mechanicalReduction>10</mechanicalReduction>
      <hardwareInterface>hardware_interface/EffortJointInterface</hardwareInterface>
    </actuator>
  </transmission>

  <transmission name="LB_mid_trans">
    <type>transmission_interface/SimpleTransmission</type>
    <joint name="LB_mid_joint">
      <hardwareInterface>hardware_interface/EffortJointInterface</hardwareInterface>
      <!--Note that the value of this tag should be EffortJointInterface when this transmission is loaded in Gazebo -->
    </joint>
    <actuator name="LB_mid_motor">
      <!--An actuator the transmission is connected to. The actuator is specified by its name attribute, and the following sub-elements -->
      <mechanicalReduction>10</mechanicalReduction>
      <hardwareInterface>hardware_interface/EffortJointInterface</hardwareInterface>
    </actuator>
  </transmission>

  <transmission name="LB_down_trans">
    <type>transmission_interface/SimpleTransmission</type>
    <joint name="LB_down_joint">
      <hardwareInterface>hardware_interface/EffortJointInterface</hardwareInterface>
      <!--Note that the value of this tag should be EffortJointInterface when this transmission is loaded in Gazebo -->
    </joint>
    <actuator name="LB_down_motor">
      <!--An actuator the transmission is connected to. The actuator is specified by its name attribute, and the following sub-elements -->
      <mechanicalReduction>10</mechanicalReduction>
      <hardwareInterface>hardware_interface/EffortJointInterface</hardwareInterface>
    </actuator>
  </transmission>

  <transmission name="RB_top_trans">
    <type>transmission_interface/SimpleTransmission</type>
    <joint name="RB_top_joint">
      <hardwareInterface>hardware_interface/EffortJointInterface</hardwareInterface>
      <!--Note that the value of this tag should be EffortJointInterface when this transmission is loaded in Gazebo -->
    </joint>
    <actuator name="RB_top_motor">
      <!--An actuator the transmission is connected to. The actuator is specified by its name attribute, and the following sub-elements -->
      <mechanicalReduction>10</mechanicalReduction>
      <hardwareInterface>hardware_interface/EffortJointInterface</hardwareInterface>
    </actuator>
  </transmission>

  <transmission name="RB_mid_trans">
    <type>transmission_interface/SimpleTransmission</type>
    <joint name="RB_mid_joint">
      <hardwareInterface>hardware_interface/EffortJointInterface</hardwareInterface>
      <!--Note that the value of this tag should be EffortJointInterface when this transmission is loaded in Gazebo -->
    </joint>
    <actuator name="RB_mid_motor">
      <!--An actuator the transmission is connected to. The actuator is specified by its name attribute, and the following sub-elements -->
      <mechanicalReduction>10</mechanicalReduction>
      <hardwareInterface>hardware_interface/EffortJointInterface</hardwareInterface>
    </actuator>
  </transmission>

  <transmission name="RB_down_trans">
    <type>transmission_interface/SimpleTransmission</type>
    <joint name="RB_down_joint">
      <hardwareInterface>hardware_interface/EffortJointInterface</hardwareInterface>
      <!--Note that the value of this tag should be EffortJointInterface when this transmission is loaded in Gazebo -->
    </joint>
    <actuator name="RB_down_motor">
      <!--An actuator the transmission is connected to. The actuator is specified by its name attribute, and the following sub-elements -->
      <mechanicalReduction>10</mechanicalReduction>
      <hardwareInterface>hardware_interface/EffortJointInterface</hardwareInterface>
    </actuator>
  </transmission>

  <gazebo reference="LF_top_link">
    <material>Gazebo/SkyBlue</material>
    <mu1>0.5</mu1>
    <mu2>0.5</mu2>
  </gazebo>

  <gazebo reference="LF_mid_link">
    <material>Gazebo/SkyBlue</material>
    <mu1>0.5</mu1>
    <mu2>0.5</mu2>
  </gazebo>

  <gazebo reference="LF_down_link">
    <material>Gazebo/SkyBlue</material>
    <mu1>0.5</mu1>
    <mu2>0.5</mu2>
  </gazebo>

  <gazebo reference="RF_top_link">
    <material>Gazebo/SkyBlue</material>
    <mu1>0.5</mu1>
    <mu2>0.5</mu2>
  </gazebo>

  <gazebo reference="RF_mid_link">
    <material>Gazebo/SkyBlue</material>
    <mu1>0.5</mu1>
    <mu2>0.5</mu2>
  </gazebo>

  <gazebo reference="RF_down_link">
    <material>Gazebo/SkyBlue</material>
    <mu1>0.5</mu1>
    <mu2>0.5</mu2>
  </gazebo>

  <gazebo reference="LB_top_link">
    <material>Gazebo/SkyBlue</material>
    <mu1>0.5</mu1>
    <mu2>0.5</mu2>
  </gazebo>

  <gazebo reference="LB_mid_link">
    <material>Gazebo/SkyBlue</material>
    <mu1>0.5</mu1>
    <mu2>0.5</mu2>
  </gazebo>

  <gazebo reference="LB_down_link">
    <material>Gazebo/SkyBlue</material>
    <mu1>0.5</mu1>
    <mu2>0.5</mu2>
  </gazebo>

  <gazebo reference="RB_top_link">
    <material>Gazebo/SkyBlue</material>
    <mu1>0.5</mu1>
    <mu2>0.5</mu2>
  </gazebo>

  <gazebo reference="RB_mid_link">
    <material>Gazebo/SkyBlue</material>
    <mu1>0.5</mu1>
    <mu2>0.5</mu2>
  </gazebo>

  <gazebo reference="RB_down_link">
    <material>Gazebo/SkyBlue</material>
    <mu1>0.5</mu1>
    <mu2>0.5</mu2>
  </gazebo>

  <gazebo>
    <plugin filename="libgazebo_ros_control.so" name="gazebo_ros_control">
      <robotNamespace>/dog_v4</robotNamespace>
      <!-- <robotNamespace>: The ROS namespace to be used for this instance of the plugin, defaults to robot name in URDF/SDF -->
      <robotSimType>gazebo_ros_control/DefaultRobotHWSim</robotSimType>
      <!--By default, without a <robotSimType> tag, gazebo_ros_control will attempt to get all of the information it needs to interface with a ros_control-based controller out of the URDF. -->
    </plugin>
  </gazebo>
</robot>

