<?xml version="1.0" ?>
<robot name="che0etah_model" xmlns:xacro="http://www.w3.org/2007/XMLSchema-versioning" >

    <!-- Import gazebo elements-->
    <xacro:include filename="$(find cheetah_model)/urdf/cheetah_model.gazebo.xacro" />

    <!-- Define some params-->
    <xacro:property name="body_mass" value="4.0"/>
    <xacro:property name="shoulder_mass" value="1.0"/>
    <xacro:property name="hip_mass" value="3.0"/>
    <xacro:property name="knee_mass" value="1.5"/>
    <xacro:property name="motor_fri" value="1.0"/>
    <xacro:property name="motor_damp" value="1.0"/>


    <link name="world_link"/>
    <link name="body_link">
        <inertial>
            <origin xyz="4.7665E-11 -9.774E-11 7.8204E-09" rpy="0 0 0" />
            <mass value="${body_mass}" />
            <inertia ixx="1.9268" ixy="2.1744E-07" ixz="6.0623E-11"
                     iyy="0.39868" iyz="-7.9898E-07" izz="2.1621" />
        </inertial>
        <visual>
            <origin xyz="0 0 0" rpy="0 0 0" />
            <geometry>
                <mesh filename="package://cheetah_model/meshes/body_link.STL" />
            </geometry>
            <material name="">
                <color rgba="1 1 1 1" />
            </material>
        </visual>
        <collision>
            <origin xyz="0 0 0.0" rpy="0 0 0" />
            <geometry>
                <mesh filename="package://cheetah_model/meshes/body_link.STL" />
            </geometry>
        </collision>
    </link>
    <joint name="world_joint" type="fixed">
        <parent link="world_link" />
        <child link="body_link" />
    </joint>

    <link name="LF_shoulder_link">
        <inertial>
            <origin xyz="-0.050197 1.6579E-09 0.025721" rpy="0 0 0" />
            <mass value="${shoulder_mass}" />
            <inertia ixx="0.0075672" ixy="5.1432E-09" ixz="-3.4681E-09"
                     iyy="0.0078331" iyz="2.7873E-09" izz="0.0045551" />
        </inertial>
        <visual>
            <origin xyz="0 0 0" rpy="0 0 0" />
            <geometry>
                <mesh filename="package://cheetah_model/meshes/LF_shoulder_link.STL" />
            </geometry>
            <material name="">
                <color rgba="1 0 0 1" />
            </material>
        </visual>
        <collision>
            <origin xyz="0 0 0" rpy="0 0 0" />
            <geometry>
                <mesh filename="package://cheetah_model/meshes/LF_shoulder_link.STL" />
            </geometry>
        </collision>
    </link>
    <joint name="body_to_LF_shoulder" type="revolute">
        <origin xyz="0.2 -0.3498 0" rpy="1.5708 0 1.5708" />
        <parent link="body_link" />
        <child link="LF_shoulder_link" />
        <axis xyz="1 0 0" />
        <limit lower="-1.57" upper="1.57"
               effort="300" velocity="12.56" />
        <dynamics damping="${motor_damp}" friction="${motor_fri}" />
    </joint>

    <link name="LF_hip_link">
        <inertial>
            <origin xyz="-0.05 -0.1259 0" rpy="0 0 0" />
            <mass value="${hip_mass}" />
            <inertia ixx="0.13447" ixy="2.7733E-17" ixz="-4.1134E-18"
                     iyy="0.020174" iyz="2.5177E-17" izz="0.13014" />
        </inertial>
        <visual>
            <origin xyz="0 0 0" rpy="0 0 0" />
            <geometry>
                <mesh filename="package://cheetah_model/meshes/LF_hip_link.STL" />
            </geometry>
            <material name="">
                <color rgba="0 1 0 1" />
            </material>
        </visual>
        <collision>
            <origin xyz="0 0 0" rpy="0 0 0" />
            <geometry>
                <mesh filename="package://cheetah_model/meshes/LF_hip_link.STL" />
            </geometry>
        </collision>
    </link>
    <joint name="LF_shoulder_to_LF_hip" type="revolute">
        <origin xyz="-0.050197 0 0.1" rpy="0 1.5708 0" />
        <parent link="LF_shoulder_link" />
        <child link="LF_hip_link" />
        <axis xyz="-1 0 0" />
        <limit lower="-3.14" upper="3.14"
               effort="300" velocity="12.56" />
        <dynamics damping="${motor_damp}" friction="${motor_fri}" />
    </joint>

    <link name="LF_knee_link">
        <inertial>
            <origin xyz="-0.0325 -0.1327 7.0855E-10" rpy="0 0 0" />
            <mass value="${knee_mass}" />
            <inertia ixx="0.041846" ixy="1.8339E-10" ixz="3.4138E-09"
                     iyy="0.0022039" iyz="3.2982E-10" izz="0.041328" />
        </inertial>
        <visual>
            <origin xyz="0 0 0" rpy="0 0 0" />
            <geometry>
                <mesh filename="package://cheetah_model/meshes/LF_knee_link.STL" />
            </geometry>
            <material name="">
                <color rgba="0 0 1 1" />
            </material>
        </visual>
        <collision>
            <origin xyz="0 0 0" rpy="0 0 0" />
            <geometry>
                <mesh filename="package://cheetah_model/meshes/LF_knee_link.STL" />
            </geometry>
<!--            <surface>-->
<!--                <friction>-->
<!--                    <ode>-->
<!--                        <mu>10.0</mu>-->
<!--                        <mu2>10.0</mu2>-->
<!--                    </ode>-->
<!--                </friction>-->
<!--            </surface>-->
        </collision>
    </link>
    <joint name="LF_hip_to_LF_knee" type="revolute">
        <origin xyz="-0.0175 -0.35 0" rpy="0 0 0" />
        <parent link="LF_hip_link" />
        <child link="LF_knee_link" />
        <axis xyz="-1 0 0" />
        <limit lower="-3.14" upper="3.14"
               effort="300" velocity="12.56" />
        <dynamics damping="${motor_damp}" friction="${motor_fri}" />
    </joint>

    <link name="RF_shoulder_link">
        <inertial>
            <origin xyz="-0.050197 4.7329E-09 0.025721" rpy="0 0 0" />
            <mass value="${shoulder_mass}" />
            <inertia ixx="0.0075672" ixy="6.0059E-09" ixz="-3.3928E-09"
                     iyy="0.0078331" iyz="2.6669E-09" izz="0.0045551" />
        </inertial>
        <visual>
            <origin xyz="0 0 0" rpy="0 0 0" />
            <geometry>
                <mesh filename="package://cheetah_model/meshes/RF_shoulder_link.STL" />
            </geometry>
            <material name="">
                <color rgba="1 0 0 1" />
            </material>
        </visual>
        <collision>
            <origin xyz="0 0 0" rpy="0 0 0" />
            <geometry>
                <mesh filename="package://cheetah_model/meshes/RF_shoulder_link.STL" />
            </geometry>
        </collision>
    </link>
    <joint name="body_to_RF_shoulder" type="revolute">
        <origin xyz="-0.2 -0.3498 0" rpy="-1.5708 0 1.5708" />
        <parent link="body_link" />
        <child link="RF_shoulder_link" />
        <axis xyz="-1 0 0" />
        <limit lower="-1.57" upper="1.57"
               effort="300" velocity="12.56" />
        <dynamics damping="${motor_damp}" friction="${motor_fri}" />
    </joint>

    <link name="RF_hip_link">
        <inertial>
            <origin xyz="-0.05 -0.125901750874251 0" rpy="0 0 0" />
            <mass value="${hip_mass}" />
            <inertia ixx="0.134474751410522" ixy="-10.00856843872561E-18" ixz="-3.2778892928792E-18"
                     iyy="0.0201741931777721" iyz="-2.89770588449339E-18" izz="0.130137705098105" />
        </inertial>
        <visual>
            <origin xyz="0 0 0" rpy="0 0 0" />
            <geometry>
                <mesh filename="package://cheetah_model/meshes/RF_hip_link.STL" />
            </geometry>
            <material name="">
                <color rgba="0 1 0 1" />
            </material>
        </visual>
        <collision>
            <origin xyz="0 0 0" rpy="0 0 0" />
            <geometry>
                <mesh filename="package://cheetah_model/meshes/RF_hip_link.STL" />
            </geometry>
        </collision>
    </link>
    <joint name="RF_shoulder_to_RF_hip" type="revolute">
        <origin xyz="-0.050197 0 0.1" rpy="3.1416 1.5708 0" />
        <parent link="RF_shoulder_link" />
        <child link="RF_hip_link" />
        <axis xyz="1 0 0" />
        <limit lower="-3.14" upper="3.14"
               effort="300" velocity="12.56" />
        <dynamics damping="${motor_damp}" friction="${motor_fri}" />
    </joint>

    <link name="RF_knee_link">
        <inertial>
            <origin xyz="-0.0324999996259642 -0.132703983194415 7.08550385031259E-10" rpy="0 0 0" />
            <mass value="${knee_mass}" />
            <inertia ixx="0.0418458834907561" ixy="1.83391853856617E-10" ixz="3.41384812112721E-09"
                     iyy="0.00220392060914795" iyz="3.29819463915723E-10" izz="0.041327893755322" />
        </inertial>
        <visual>
            <origin xyz="0 0 0" rpy="0 0 0" />
            <geometry>
                <mesh filename="package://cheetah_model/meshes/RF_knee_link.STL" />
            </geometry>
            <material name="">
                <color rgba="0 0 1 1" />
            </material>
        </visual>
        <collision>
            <origin xyz="0 0 0" rpy="0 0 0" />
            <geometry>
                <mesh filename="package://cheetah_model/meshes/RF_knee_link.STL" />
            </geometry>
        </collision>
<!--        <surface>
            <friction>
                <ode>
                    <mu>10.0</mu>
                    <mu2>10.0</mu2>
                </ode>
            </friction>
        </surface>-->
    </link>
    <joint name="RF_hip_to_RF_knee" type="revolute">
        <origin xyz="-0.0175 -0.35 0" rpy="0 0 0" />
        <parent link="RF_hip_link" />
        <child link="RF_knee_link" />
        <axis xyz="1 0 0" />
        <limit lower="-3.14" upper="3.14"
               effort="300" velocity="12.56" />
        <dynamics damping="${motor_damp}" friction="${motor_fri}" />
    </joint>

    <link name="LH_shoulder_link">
        <inertial>
            <origin xyz="-0.0501973749554487 -4.56687991009661E-09 -0.025721456770399" rpy="0 0 0" />
            <mass value="${shoulder_mass}" />
            <inertia ixx="0.00756715122480539" ixy="-5.34881333358175E-09" ixz="3.67813128999948E-09"
                     iyy="0.00783306249669744" iyz="2.67306826420829E-09" izz="0.00455513672380048" />
        </inertial>
        <visual>
            <origin xyz="0 0 0" rpy="0 0 0" />
            <geometry>
                <mesh filename="package://cheetah_model/meshes/LH_shoulder_link.STL" />
            </geometry>
            <material name="">
                <color rgba="1 0 0 1" />
            </material>
        </visual>
        <collision>
            <origin xyz="0 0 0" rpy="0 0 0" />
            <geometry>
                <mesh filename="package://cheetah_model/meshes/LH_shoulder_link.STL" />
            </geometry>
        </collision>
    </link>
    <joint name="body_to_LH_shoulder" type="revolute">
        <origin xyz="0.2 0.3498 0" rpy="1.5708 0 -1.5708" />
        <parent link="body_link" />
        <child link="LH_shoulder_link" />
        <axis xyz="1 0 0" />
        <limit lower="-1.57" upper="1.57"
               effort="300" velocity="12.56" />
        <dynamics damping="${motor_damp}" friction="${motor_fri}" />
    </joint>

    <link name="LH_hip_link">
        <inertial>
            <origin xyz="-0.05 -0.125901750874251 -5.55111512312578E-17" rpy="0 0 0" />
            <mass value="${hip_mass}" />
            <inertia ixx="0.134474751410522" ixy="3.07558660643736E-17" ixz="-7.77149275029767E-18"
                     iyy="0.0201741931777721" iyz="1.96934042288402E-17" izz="0.130137705098105" />
        </inertial>
        <visual>
            <origin xyz="0 0 0" rpy="0 0 0" />
            <geometry>
                <mesh filename="package://cheetah_model/meshes/LH_hip_link.STL" />
            </geometry>
            <material name="">
                <color rgba="0 1 0 1" />
            </material>
        </visual>
        <collision>
            <origin xyz="0 0 0" rpy="0 0 0" />
            <geometry>
                <mesh filename="package://cheetah_model/meshes/LH_hip_link.STL" />
            </geometry>
        </collision>
    </link>
    <joint name="LH_shoulder_to_LH_hip" type="revolute">
        <origin xyz="-0.050197 0 -0.1" rpy="0 -1.5708 0" />
        <parent link="LH_shoulder_link" />
        <child link="LH_hip_link" />
        <axis xyz="-1 0 0" />
        <limit lower="-3.14" upper="3.14"
               effort="300" velocity="12.56" />
        <dynamics damping="${motor_damp}" friction="${motor_fri}" />
    </joint>

    <link name="LH_knee_link">
        <inertial>
            <origin xyz="-0.0324999996259642 -0.132703983194415 7.08550274008957E-10" rpy="0 0 0" />
            <mass value="${knee_mass}" />
            <inertia ixx="0.0418458834907562" ixy="1.83391852955885E-10" ixz="3.413848122736E-09"
                     iyy="0.00220392060914796" iyz="3.29819458134421E-10" izz="0.041327893755322" />
        </inertial>
        <visual>
            <origin xyz="0 0 0" rpy="0 0 0" />
            <geometry>
                <mesh filename="package://cheetah_model/meshes/LH_knee_link.STL" />
            </geometry>
            <material name="">
                <color rgba="0 0 1 1" />
            </material>
        </visual>
        <collision>
            <origin xyz="0 0 0" rpy="0 0 0" />
            <geometry>
                <mesh filename="package://cheetah_model/meshes/LH_knee_link.STL" />
            </geometry>
<!--            <surface>-->
<!--                <friction>-->
<!--                    <ode>-->
<!--                        <mu>10.0</mu>-->
<!--                        <mu2>10.0</mu2>-->
<!--                    </ode>-->
<!--                </friction>-->
<!--            </surface>-->
        </collision>
    </link>
    <joint name="LH_hip_to_LH_knee" type="revolute">
        <origin xyz="-0.0175 -0.35 0" rpy="0 0 0" />
        <parent link="LH_hip_link" />
        <child link="LH_knee_link" />
        <axis xyz="-1 0 0" />
        <limit lower="-3.14" upper="3.14"
               effort="300" velocity="12.56" />
        <dynamics damping="${motor_damp}" friction="${motor_fri}" />
    </joint>

    <link name="RH_shoulder_link">
        <inertial>
            <origin xyz="-0.0501973799779306 -1.52221795247363E-09 -0.025721453293929" rpy="0 0 0" />
            <mass value="${shoulder_mass}" />
            <inertia ixx="0.0075671504774973" ixy="-5.26651026494318E-09" ixz="3.48220543176805E-09"
                     iyy="0.00783306122929005" iyz="2.78554516211265E-09" izz="0.00455513495958608" />
        </inertial>
        <visual>
            <origin xyz="0 0 0" rpy="0 0 0" />
            <geometry>
                <mesh filename="package://cheetah_model/meshes/RH_shoulder_link.STL" />
            </geometry>
            <material name="">
                <color rgba="1 0 0 1" />
            </material>
        </visual>
        <collision>
            <origin xyz="0 0 0" rpy="0 0 0" />
            <geometry>
                <mesh filename="package://cheetah_model/meshes/RH_shoulder_link.STL" />
            </geometry>
        </collision>
    </link>
    <joint name="body_to_RH_shoulder" type="revolute">
        <origin xyz="-0.2 0.3498 0" rpy="-1.5708 0 -1.5708" />
        <parent link="body_link" />
        <child link="RH_shoulder_link" />
        <axis xyz="-1 0 0" />
        <limit lower="-1.57" upper="1.57"
               effort="300" velocity="12.56" />
        <dynamics damping="${motor_damp}" friction="${motor_fri}" />
    </joint>

    <link name="RH_hip_link">
        <inertial>
            <origin xyz="-0.05 -0.125901750874251 -5.55111512312578E-17" rpy="0 0 0" />
            <mass value="${hip_mass}" />
            <inertia ixx="0.134474751410522" ixy="-5.34419819342539E-19" ixz="-3.36867247431082E-18"
                     iyy="0.0201741931777721" iyz="-3.31583569187149E-18" izz="0.130137705098105" />
        </inertial>
        <visual>
            <origin xyz="0 0 0" rpy="0 0 0" />
            <geometry>
                <mesh filename="package://cheetah_model/meshes/RH_hip_link.STL" />
            </geometry>
            <material name="">
                <color rgba="0 1 0 1" />
            </material>
        </visual>
        <collision>
            <origin xyz="0 0 0" rpy="0 0 0" />
            <geometry>
                <mesh filename="package://cheetah_model/meshes/RH_hip_link.STL" />
            </geometry>
        </collision>
    </link>
    <joint name="RH_shoulder_to_RH_hip" type="revolute">
        <origin xyz="-0.050197 0 -0.1" rpy="3.1416 -1.5708 0" />
        <parent link="RH_shoulder_link" />
        <child link="RH_hip_link" />
        <axis xyz="1 0 0" />
        <limit lower="-3.14" upper="3.14"
               effort="300" velocity="12.56" />
        <dynamics damping="${motor_damp}" friction="${motor_fri}" />
    </joint>

    <link name="RH_knee_link">
        <inertial>
            <origin xyz="-0.0324999996259642 -0.132703983194415 7.08550274008957E-10" rpy="0 0 0" />
            <mass value="${knee_mass}" />
            <inertia ixx="0.0418458834907561" ixy="1.8339185505944E-10" ixz="3.41384812216053E-09"
                     iyy="0.00220392060914795" iyz="3.29819463826677E-10" izz="0.041327893755322" />
        </inertial>
        <visual>
            <origin xyz="0 0 0" rpy="0 0 0" />
            <geometry>
                <mesh filename="package://cheetah_model/meshes/RH_knee_link.STL" />
            </geometry>
            <material name="">
                <color rgba="0 0 1 1" />
            </material>
        </visual>
        <collision>
            <origin xyz="0 0 0" rpy="0 0 0" />
            <geometry>
                <mesh filename="package://cheetah_model/meshes/RH_knee_link.STL" />
            </geometry>
        </collision>
    </link>
    <joint name="RH_hip_to_RH_knee" type="revolute">
        <origin xyz="-0.0175 -0.35 0" rpy="0 0 0" />
        <parent link="RH_hip_link" />
        <child link="RH_knee_link" />
        <axis xyz="1 0 0" />
        <limit lower="-3.14" upper="3.14"
               effort="300" velocity="12.56" />
        <dynamics damping="${motor_damp}" friction="${motor_fri}" />
    </joint>

    <!--Transmission and actuators-->
    <transmission name="LF_shoulder_transmission">
        <type>transmission_interface/SimpleTransmission</type>
        <joint name="body_to_LF_shoulder">
            <hardwareInterface>hardware_interface/EffortJointInterface</hardwareInterface>
        </joint>
        <actuator name="LF_shoulder_motor">
            <hardwareInterface>EffortJointInterface</hardwareInterface>
            <mechanicalReduction>1</mechanicalReduction>
        </actuator>
    </transmission>
    <transmission name="LF_hip_transmission">
        <type>transmission_interface/SimpleTransmission</type>
        <joint name="LF_shoulder_to_LF_hip">
            <hardwareInterface>hardware_interface/EffortJointInterface</hardwareInterface>
        </joint>
        <actuator name="LF_hip_motor">
            <hardwareInterface>EffortJointInterface</hardwareInterface>
            <mechanicalReduction>1</mechanicalReduction>
        </actuator>
    </transmission>
    <transmission name="LF_knee_transmission">
        <type>transmission_interface/SimpleTransmission</type>
        <joint name="LF_hip_to_LF_knee">
            <hardwareInterface>hardware_interface/EffortJointInterface</hardwareInterface>
        </joint>
        <actuator name="LF_knee_motor">
            <hardwareInterface>EffortJointInterface</hardwareInterface>
            <mechanicalReduction>1</mechanicalReduction>
        </actuator>
    </transmission>

    <transmission name="RF_shoulder_transmission">
        <type>transmission_interface/SimpleTransmission</type>
        <joint name="body_to_RF_shoulder">
            <hardwareInterface>hardware_interface/EffortJointInterface</hardwareInterface>
        </joint>
        <actuator name="RF_shoulder_motor">
            <hardwareInterface>EffortJointInterface</hardwareInterface>
            <mechanicalReduction>1</mechanicalReduction>
        </actuator>
    </transmission>
    <transmission name="RF_hip_transmission">
        <type>transmission_interface/SimpleTransmission</type>
        <joint name="RF_shoulder_to_RF_hip">
            <hardwareInterface>hardware_interface/EffortJointInterface</hardwareInterface>
        </joint>
        <actuator name="RF_hip_motor">
            <hardwareInterface>EffortJointInterface</hardwareInterface>
            <mechanicalReduction>1</mechanicalReduction>
        </actuator>
    </transmission>
    <transmission name="RF_knee_transmission">
        <type>transmission_interface/SimpleTransmission</type>
        <joint name="RF_hip_to_RF_knee">
            <hardwareInterface>hardware_interface/EffortJointInterface</hardwareInterface>
        </joint>
        <actuator name="RF_knee_motor">
            <hardwareInterface>EffortJointInterface</hardwareInterface>
            <mechanicalReduction>1</mechanicalReduction>
        </actuator>
    </transmission>

    <transmission name="LH_shoulder_transmission">
        <type>transmission_interface/SimpleTransmission</type>
        <joint name="body_to_LH_shoulder">
            <hardwareInterface>hardware_interface/EffortJointInterface</hardwareInterface>
        </joint>
        <actuator name="LH_shoulder_motor">
            <hardwareInterface>EffortJointInterface</hardwareInterface>
            <mechanicalReduction>1</mechanicalReduction>
        </actuator>
    </transmission>
    <transmission name="LH_hip_transmission">
        <type>transmission_interface/SimpleTransmission</type>
        <joint name="LH_shoulder_to_LH_hip">
            <hardwareInterface>hardware_interface/EffortJointInterface</hardwareInterface>
        </joint>
        <actuator name="LH_hip_motor">
            <hardwareInterface>EffortJointInterface</hardwareInterface>
            <mechanicalReduction>1</mechanicalReduction>
        </actuator>
    </transmission>
    <transmission name="LH_knee_transmission">
        <type>transmission_interface/SimpleTransmission</type>
        <joint name="LH_hip_to_LH_knee">
            <hardwareInterface>hardware_interface/EffortJointInterface</hardwareInterface>
        </joint>
        <actuator name="LH_knee_motor">
            <hardwareInterface>EffortJointInterface</hardwareInterface>
            <mechanicalReduction>1</mechanicalReduction>
        </actuator>
    </transmission>

    <transmission name="RH_shoulder_transmission">
        <type>transmission_interface/SimpleTransmission</type>
        <joint name="body_to_RH_shoulder">
            <hardwareInterface>hardware_interface/EffortJointInterface</hardwareInterface>
        </joint>
        <actuator name="RH_shoulder_motor">
            <hardwareInterface>EffortJointInterface</hardwareInterface>
            <mechanicalReduction>1</mechanicalReduction>
        </actuator>
    </transmission>
    <transmission name="RH_hip_transmission">
        <type>transmission_interface/SimpleTransmission</type>
        <joint name="RH_shoulder_to_RH_hip">
            <hardwareInterface>hardware_interface/EffortJointInterface</hardwareInterface>
        </joint>
        <actuator name="RH_hip_motor">
            <hardwareInterface>EffortJointInterface</hardwareInterface>
            <mechanicalReduction>1</mechanicalReduction>
        </actuator>
    </transmission>
    <transmission name="RH_knee_transmission">
        <type>transmission_interface/SimpleTransmission</type>
        <joint name="RH_hip_to_RH_knee">
            <hardwareInterface>hardware_interface/EffortJointInterface</hardwareInterface>
        </joint>
        <actuator name="RH_knee_motor">
            <hardwareInterface>EffortJointInterface</hardwareInterface>
            <mechanicalReduction>1</mechanicalReduction>
        </actuator>
    </transmission>

</robot>
